#VRML_SIM R2021b utf8
# license: Apache License 2.0
# license url: http://www.apache.org/licenses/LICENSE-2.0
# This is a proto file for Webots for the imandrabot
# Extracted from: /tmp/tmp2jrni82y.urdf

PROTO imandrabot [
  field  SFVec3f     translation     0 0 0
  field  SFRotation  rotation        0 1 0 0
  field  SFString    name            "imandrabot"  # Is `Robot.name`.
  field  SFString    controller      "void"        # Is `Robot.controller`.
  field  MFString    controllerArgs  []            # Is `Robot.controllerArgs`.
  field  SFString    customData      ""            # Is `Robot.customData`.
  field  SFBool      supervisor      FALSE         # Is `Robot.supervisor`.
  field  SFBool      synchronization TRUE          # Is `Robot.synchronization`.
  field  SFBool      selfCollision   FALSE         # Is `Robot.selfCollision`.
]
{
  Robot {
    translation IS translation
    rotation IS rotation
    controller IS controller
    controllerArgs IS controllerArgs
    customData IS customData
    supervisor IS supervisor
    synchronization IS synchronization
    selfCollision IS selfCollision
    children [
      Shape {
        appearance PBRAppearance {
          baseColor 0.500000 0.500000 0.500000
          transparency 0.000000
          roughness 1.000000
          metalness 0
          emissiveColor 0.000000 0.000000 0.000000
        }
        geometry Box {
           size 0.12 0.02 0.06
        }
      }
      Transform {
        translation -0.057000 0.000000 -0.030000
        rotation 0.000000 1.000000 0.000000 0.000000
        children [
          Shape {
            appearance PBRAppearance {
              baseColor 0.500000 0.500000 0.500000
              transparency 0.000000
              roughness 1.000000
              metalness 0
              emissiveColor 0.000000 0.000000 0.000000
            }
            geometry Sphere {
              radius 0.002
            }
          }
        ]
      }
      Solid {
        translation 0.030000 0.000000 0.000000
        rotation 0.000000 1.000000 0.000000 0.000000
        children [
          Shape {
            appearance PBRAppearance {
              baseColor 0.500000 0.500000 0.500000
              transparency 0.000000
              roughness 1.000000
              metalness 0
              emissiveColor 0.000000 0.000000 0.000000
            }
            geometry Box {
               size 0.01 0.12 0.005
            }
          }
          Solid {
            translation 0.000000 0.080000 0.000000
            rotation 0.000000 1.000000 0.000000 0.000000
            children [
              Shape {
                appearance PBRAppearance {
                  baseColor 0.500000 0.500000 0.500000
                  transparency 0.000000
                  roughness 1.000000
                  metalness 0
                  emissiveColor 0.000000 0.000000 0.000000
                }
                geometry Sphere {
                  radius 0.03
                }
              }
              HingeJoint {
                jointParameters HingeJointParameters {
                  axis 0.000000 1.000000 0.000000
                  anchor 0.000000 0.000000 0.000000
                  dampingConstant 0.0
                  staticFriction 0.0
                }
                device [
                  RotationalMotor {
                    name "leftwheel_hinge"
                    maxVelocity 1.0
                    maxTorque 10.0
                  }
                  PositionSensor {
                    name "leftwheel_hinge_sensor"
                  }
                ]
                endPoint Solid {
                  translation 0.000000 0.000000 0.000000
                  rotation 0.000000 1.000000 0.000000 0.000000
                  children [
                    Transform {
                      translation 0.000000 0.000000 0.000000
                      rotation 0.000096 1.000000 0.000000 1.570796
                      children [
                        Shape {
                          appearance PBRAppearance {
                            baseColor 0.500000 0.500000 0.500000
                            transparency 0.000000
                            roughness 1.000000
                            metalness 0
                            emissiveColor 0.000000 0.000000 0.000000
                          }
                          geometry Cylinder {
                            radius 0.035
                            height 0.005
                          }
                        }
                      ]
                    }
                  ]
                  name "leftwheel_wheel"
                  boundingObject Transform {
                    translation 0.000000 0.000000 0.000000
                    rotation 0.000096 1.000000 0.000000 1.570796
                    children [
                      Cylinder {
                        radius 0.035
                        height 0.005
                      }
                    ]
                  }
                  physics Physics {
                    density -1
                    mass 0.010000
                    centerOfMass [ 0.000000 0.000000 0.000000 ]
                    inertiaMatrix [
                      1.000000e-05 1.000000e-05 1.000000e-05
                      0.000000e+00 0.000000e+00 0.000000e+00
                    ]
                  }
                }
              }
            ]
            name "leftwheel"
            boundingObject Sphere {
              radius 0.03
            }
            physics Physics {
              density -1
              mass 0.010000
              centerOfMass [ 0.000000 0.000000 0.000000 ]
              inertiaMatrix [
                1.000000e-05 1.000000e-05 1.000000e-05
                0.000000e+00 0.000000e+00 0.000000e+00
              ]
            }
          }
          Solid {
            translation 0.000000 -0.080000 0.000000
            rotation 0.000000 1.000000 0.000000 0.000000
            children [
              Shape {
                appearance PBRAppearance {
                  baseColor 0.500000 0.500000 0.500000
                  transparency 0.000000
                  roughness 1.000000
                  metalness 0
                  emissiveColor 0.000000 0.000000 0.000000
                }
                geometry Sphere {
                  radius 0.03
                }
              }
              HingeJoint {
                jointParameters HingeJointParameters {
                  axis 0.000000 1.000000 0.000000
                  anchor 0.000000 0.000000 0.000000
                  dampingConstant 0.0
                  staticFriction 0.0
                }
                device [
                  RotationalMotor {
                    name "rightwheel_hinge"
                    maxVelocity 1.0
                    maxTorque 10.0
                  }
                  PositionSensor {
                    name "rightwheel_hinge_sensor"
                  }
                ]
                endPoint Solid {
                  translation 0.000000 0.000000 0.000000
                  rotation 0.000000 1.000000 0.000000 0.000000
                  children [
                    Transform {
                      translation 0.000000 0.000000 0.000000
                      rotation 0.000096 1.000000 0.000000 1.570796
                      children [
                        Shape {
                          appearance PBRAppearance {
                            baseColor 0.500000 0.500000 0.500000
                            transparency 0.000000
                            roughness 1.000000
                            metalness 0
                            emissiveColor 0.000000 0.000000 0.000000
                          }
                          geometry Cylinder {
                            radius 0.035
                            height 0.005
                          }
                        }
                      ]
                    }
                  ]
                  name "rightwheel_wheel"
                  boundingObject Transform {
                    translation 0.000000 0.000000 0.000000
                    rotation 0.000096 1.000000 0.000000 1.570796
                    children [
                      Cylinder {
                        radius 0.035
                        height 0.005
                      }
                    ]
                  }
                  physics Physics {
                    density -1
                    mass 0.010000
                    centerOfMass [ 0.000000 0.000000 0.000000 ]
                    inertiaMatrix [
                      1.000000e-05 1.000000e-05 1.000000e-05
                      0.000000e+00 0.000000e+00 0.000000e+00
                    ]
                  }
                }
              }
            ]
            name "rightwheel"
            boundingObject Sphere {
              radius 0.03
            }
            physics Physics {
              density -1
              mass 0.010000
              centerOfMass [ 0.000000 0.000000 0.000000 ]
              inertiaMatrix [
                1.000000e-05 1.000000e-05 1.000000e-05
                0.000000e+00 0.000000e+00 0.000000e+00
              ]
            }
          }
        ]
        name "strut"
        boundingObject Box {
           size 0.010000 0.120000 0.005000
        }
        physics Physics {
          density -1
          mass 0.010000
          centerOfMass [ 0.000000 0.000000 0.000000 ]
          inertiaMatrix [
            1.202083e-05 1.041667e-07 1.208333e-05
            0.000000e+00 0.000000e+00 0.000000e+00
          ]
        }
      }
      Solid {
        translation 0.060000 0.000000 0.000000
        rotation 0.000000 1.000000 0.000000 0.000000
        children [
          Shape {
            appearance PBRAppearance {
              baseColor 0.500000 0.500000 0.500000
              transparency 0.000000
              roughness 1.000000
              metalness 0
              emissiveColor 0.000000 0.000000 0.000000
            }
            geometry Sphere {
              radius 0.002
            }
          }
          Lidar {
            name "lidar"
            fieldOfView 3.141592
            horizontalResolution 180
            numberOfLayers 1
            minRange 0.100000
            maxRange 1.000000
            noise 0.010000
            resolution 0.010000
          }
        ]
        name "scanner"
        physics Physics {
          density -1
          mass 0.000001
          centerOfMass [ 0.000000 0.000000 0.000000 ]
          inertiaMatrix [
            1.000000e-08 1.000000e-07 1.000000e-07
            0.000000e+00 0.000000e+00 0.000000e+00
          ]
        }
      }
    ]
    name IS name 
    boundingObject Group {
      children [
        Box {
           size 0.120000 0.020000 0.060000
        }
        Transform {
          translation -0.057000 0.000000 -0.030000
          rotation 0.000000 1.000000 0.000000 0.000000
          children [
            Sphere {
              radius 0.002
            }
          ]
        }
      ]
    }
    physics Physics {
      density -1
      mass 1.000000
      centerOfMass [ 0.000000 0.000000 0.000000 ]
      inertiaMatrix [
        3.333333e-04 6.000000e-04 3.333333e-04
        0.000000e+00 0.000000e+00 0.000000e+00
      ]
    }
  }
}
